<sdf version='1.6'>
  <model name='master'>
  <static> false </static>
    <link name='right_top_panel'>
      <pose frame=''>0 0 0 0 -0 0</pose>
      <inertial>
        <pose frame=''>0.03648 0.008713 0.040499 0 -0 0</pose>
        <mass>0.58739</mass>
        <inertia>
          <ixx>1</ixx>
          <ixy>0</ixy>
          <ixz>0</ixz>
          <iyy>1</iyy>
          <iyz>0</iyz>
          <izz>1</izz>
        </inertia>
      </inertial>
      <collision name='right_top_panel_collision'>
        <pose frame=''>0 0 0 0 -0 0</pose>
        <geometry>
          <mesh>
            <scale>1 1 1</scale>
            <uri>model://MTM/meshes/right_top_panel.STL</uri>
          </mesh>
        </geometry>
      </collision>
      <visual name='right_top_panel_visual'>
        <pose frame=''>0 0 0 0 -0 0</pose>
        <geometry>
          <mesh>
            <scale>1 1 1</scale>
            <uri>model://MTM/meshes/right_top_panel.STL</uri>
          </mesh>
        </geometry>
      </visual>
    </link>

    <joint name='right_fixed_joint' type='fixed'>
      <child>right_top_panel</child>
      <parent>world</parent>
    </joint>

    <link name='right_outer_yaw_link'>
      <pose frame=''>0 0 -0.21537+1 0 -0 0</pose>
      <inertial>
        <pose frame=''>0.013424 0.062051 0.13219 0 -0 0</pose>
        <mass>1.0912</mass>
        <inertia>
          <ixx>0.0071198</ixx>
          <ixy>0.00026822</ixy>
          <ixz>-0.0005779</ixz>
          <iyy>0.0059149</iyy>
          <iyz>0.0027188</iyz>
          <izz>0.0013189</izz>
        </inertia>
      </inertial>
      <collision name='right_outer_yaw_link_collision'>
        <pose frame=''>0 0 0 0 -0 0</pose>
        <geometry>
          <mesh>
            <scale>1 1 1</scale>
            <uri>model://MTM/meshes/right_outer_yaw_link.STL</uri>
          </mesh>
        </geometry>
      </collision>
      <visual name='right_outer_yaw_link_visual'>
        <pose frame=''>0 0 0 0 -0 0</pose>
        <geometry>
          <mesh>
            <scale>1 1 1</scale>
            <uri>model://MTM/meshes/right_outer_yaw_link.STL</uri>
          </mesh>
        </geometry>
      </visual>
    </link>
    
    <joint name='right_outer_yaw_joint' type='revolute'>
      <child>right_outer_yaw_link</child>
      <parent>right_top_panel</parent>
      <axis>
        <xyz>0 0 1</xyz>
        <limit>
          <lower>-1</lower>
          <upper>1</upper>
          <effort>1</effort>
          <velocity>1</velocity>
        </limit>
        <dynamics>
          <spring_reference>0</spring_reference>
          <spring_stiffness>0</spring_stiffness>
        </dynamics>
        <use_parent_model_frame>1</use_parent_model_frame>
      </axis>
    </joint>
    <link name='right_back_parallel_link'>
      <pose frame=''>0 0 -0.21537 -1.57079 1.57079 3.14159</pose>
      <inertial>
        <pose frame=''>0.076362 -0.007849 0.00814 0 -0 0</pose>
        <mass>0.64722</mass>
        <inertia>
          <ixx>2.9358e-05</ixx>
          <ixy>3.2697e-05</ixy>
          <ixz>0.00016123</ixz>
          <iyy>0.00095009</iyy>
          <iyz>-5.7185e-06</iyz>
          <izz>0.00092305</izz>
        </inertia>
      </inertial>
      <collision name='right_back_parallel_link_collision'>
        <pose frame=''>0 0 0 0 -0 0</pose>
        <geometry>
          <mesh>
            <scale>1 1 1</scale>
            <uri>model://MTM/meshes/right_back_parallel_link.STL</uri>
          </mesh>
        </geometry>
      </collision>
      <visual name='right_back_parallel_link_visual'>
        <pose frame=''>0 0 0 0 -0 0</pose>
        <geometry>
          <mesh>
            <scale>1 1 1</scale>
            <uri>model://MTM/meshes/right_back_parallel_link.STL</uri>
          </mesh>
        </geometry>
      </visual>
    </link>
    <joint name='right_shoulder_pitch_joint' type='revolute'>
      <child>right_back_parallel_link</child>
      <parent>right_outer_yaw_link</parent>
      <axis>
        <xyz>4e-06 1 -0</xyz>
        <limit>
          <lower>-1</lower>
          <upper>1</upper>
          <effort>1</effort>
          <velocity>1</velocity>
        </limit>
        <dynamics>
          <spring_reference>0</spring_reference>
          <spring_stiffness>0</spring_stiffness>
        </dynamics>
        <use_parent_model_frame>1</use_parent_model_frame>
      </axis>
    </joint>
    <link name='right_bottom_parallel_link'>
      <pose frame=''>-1e-06 -0 -0.49504 1.5708 -0.0027 -4e-06</pose>
      <inertial>
        <pose frame=''>0.18263 0.005514 -1.2e-05 0 -0 0</pose>
        <mass>0.89273</mass>
        <inertia>
          <ixx>2.0873e-09</ixx>
          <ixy>-6.7899e-07</ixy>
          <ixz>1.572e-07</ixz>
          <iyy>0.00023271</iyy>
          <iyz>4.5867e-10</iyz>
          <izz>0.00023271</izz>
        </inertia>
      </inertial>
      <collision name='right_bottom_parallel_link_collision'>
        <pose frame=''>0 0 0 0 -0 0</pose>
        <geometry>
          <mesh>
            <scale>1 1 1</scale>
            <uri>model://MTM/meshes/right_bottom_parallel_link.STL</uri>
          </mesh>
        </geometry>
      </collision>
      <visual name='right_bottom_parallel_link_visual'>
        <pose frame=''>0 0 0 0 -0 0</pose>
        <geometry>
          <mesh>
            <scale>1 1 1</scale>
            <uri>model://MTM/meshes/right_bottom_parallel_link.STL</uri>
          </mesh>
        </geometry>
      </visual>
    </link>
    <joint name='right_elbow_pitch_joint' type='revolute'>
      <child>right_bottom_parallel_link</child>
      <parent>right_back_parallel_link</parent>
      <axis>
        <xyz>4e-06 1 -0</xyz>
        <limit>
          <lower>-1</lower>
          <upper>1</upper>
          <effort>1</effort>
          <velocity>1</velocity>
        </limit>
        <dynamics>
          <spring_reference>0</spring_reference>
          <spring_stiffness>0</spring_stiffness>
        </dynamics>
        <use_parent_model_frame>1</use_parent_model_frame>
      </axis>
    </joint>
    <link name='right_wrist_platform_link'>
      <pose frame=''>0.364091 -1e-06 -0.343456 -4e-06 -0.0027 -4e-06</pose>
      <inertial>
        <pose frame=''>0 0.075884 -0.079722 0 -0 0</pose>
        <mass>0.32541</mass>
        <inertia>
          <ixx>0</ixx>
          <ixy>0</ixy>
          <ixz>0</ixz>
          <iyy>0</iyy>
          <iyz>0</iyz>
          <izz>0</izz>
        </inertia>
      </inertial>
      <collision name='right_wrist_platform_link_collision'>
        <pose frame=''>0 0 0 0 -0 0</pose>
        <geometry>
          <mesh>
            <scale>1 1 1</scale>
            <uri>model://MTM/meshes/right_wrist_platform_link.STL</uri>
          </mesh>
        </geometry>
      </collision>
      <visual name='right_wrist_platform_link_visual'>
        <pose frame=''>0 0 0 0 -0 0</pose>
        <geometry>
          <mesh>
            <scale>1 1 1</scale>
            <uri>model://MTM/meshes/right_wrist_platform_link.STL</uri>
          </mesh>
        </geometry>
      </visual>
    </link>
    <joint name='right_wrist_platform_joint' type='revolute'>
      <child>right_wrist_platform_link</child>
      <parent>right_bottom_parallel_link</parent>
      <axis>
        <xyz>-0.0027 4e-06 0.999996</xyz>
        <limit>
          <lower>-1</lower>
          <upper>1</upper>
          <effort>1</effort>
          <velocity>1</velocity>
        </limit>
        <dynamics>
          <spring_reference>0</spring_reference>
          <spring_stiffness>0</spring_stiffness>
        </dynamics>
        <use_parent_model_frame>1</use_parent_model_frame>
      </axis>
    </joint>
    <link name='right_wrist_pitch_link'>
      <pose frame=''>0.364091 -1e-06 -0.343456 1.5708 -0.0027 -4e-06</pose>
      <inertial>
        <pose frame=''>9.6e-05 -0.061955 -0.044889 0 -0 0</pose>
        <mass>0.11725</mass>
        <inertia>
          <ixx>0</ixx>
          <ixy>0</ixy>
          <ixz>0</ixz>
          <iyy>0</iyy>
          <iyz>0</iyz>
          <izz>0</izz>
        </inertia>
      </inertial>
      <collision name='right_wrist_pitch_link_collision'>
        <pose frame=''>0 0 0 0 -0 0</pose>
        <geometry>
          <mesh>
            <scale>1 1 1</scale>
            <uri>model://MTM/meshes/right_wrist_pitch_link.STL</uri>
          </mesh>
        </geometry>
      </collision>
      <visual name='right_wrist_pitch_link_visual'>
        <pose frame=''>0 0 0 0 -0 0</pose>
        <geometry>
          <mesh>
            <scale>1 1 1</scale>
            <uri>model://MTM/meshes/right_wrist_pitch_link.STL</uri>
          </mesh>
        </geometry>
      </visual>
    </link>
    <joint name='right_wrist_pitch_joint' type='revolute'>
      <child>right_wrist_pitch_link</child>
      <parent>right_wrist_platform_link</parent>
      <axis>
        <xyz>4e-06 1 -0</xyz>
        <limit>
          <lower>-1</lower>
          <upper>1</upper>
          <effort>1</effort>
          <velocity>1</velocity>
        </limit>
        <dynamics>
          <spring_reference>0</spring_reference>
          <spring_stiffness>0</spring_stiffness>
        </dynamics>
        <use_parent_model_frame>1</use_parent_model_frame>
      </axis>
    </joint>
    <link name='right_wrist_yaw_link'>
      <pose frame=''>0.364091 -1e-06 -0.343456 3.1389 0 1.5708</pose>
      <inertial>
        <pose frame=''>-0.002136 0.049256 -0.031864 0 -0 0</pose>
        <mass>0.052383</mass>
        <inertia>
          <ixx>1.7463e-05</ixx>
          <ixy>1.081e-07</ixy>
          <ixz>5.9636e-08</ixz>
          <iyy>4.0755e-06</iyy>
          <iyz>-7.3861e-06</iyz>
          <izz>1.339e-05</izz>
        </inertia>
      </inertial>
      <collision name='right_wrist_yaw_link_collision'>
        <pose frame=''>0 0 0 0 -0 0</pose>
        <geometry>
          <mesh>
            <scale>1 1 1</scale>
            <uri>model://MTM/meshes/right_wrist_yaw_link.STL</uri>
          </mesh>
        </geometry>
      </collision>
      <visual name='right_wrist_yaw_link_visual'>
        <pose frame=''>0 0 0 0 -0 0</pose>
        <geometry>
          <mesh>
            <scale>1 1 1</scale>
            <uri>model://MTM/meshes/right_wrist_yaw_link.STL</uri>
          </mesh>
        </geometry>
      </visual>
    </link>
    <joint name='right_wrist_yaw_joint' type='revolute'>
      <child>right_wrist_yaw_link</child>
      <parent>right_wrist_pitch_link</parent>
      <axis>
        <xyz>0.002696 -0 -0.999996</xyz>
        <limit>
          <lower>-1</lower>
          <upper>1</upper>
          <effort>1</effort>
          <velocity>1</velocity>
        </limit>
        <dynamics>
          <spring_reference>0</spring_reference>
          <spring_stiffness>0</spring_stiffness>
        </dynamics>
        <use_parent_model_frame>1</use_parent_model_frame>
      </axis>
    </joint>
    <link name='right_wrist_roll_link'>
      <pose frame=''>0.364091 -1e-06 -0.343456 -1.57349 0 1.5708</pose>
      <inertial>
        <pose frame=''>0 -4e-06 -0.014612 0 -0 0</pose>
        <mass>0.0095577</mass>
        <inertia>
          <ixx>0</ixx>
          <ixy>0</ixy>
          <ixz>0</ixz>
          <iyy>0</iyy>
          <iyz>0</iyz>
          <izz>0</izz>
        </inertia>
      </inertial>
      <collision name='right_wrist_roll_link_collision'>
        <pose frame=''>0 0 0 0 -0 0</pose>
        <geometry>
          <mesh>
            <scale>1 1 1</scale>
            <uri>model://MTM/meshes/right_wrist_roll_link.STL</uri>
          </mesh>
        </geometry>
      </collision>
      <visual name='right_wrist_roll_link_visual'>
        <pose frame=''>0 0 0 0 -0 0</pose>
        <geometry>
          <mesh>
            <scale>1 1 1</scale>
            <uri>model://MTM/meshes/right_wrist_roll_link.STL</uri>
          </mesh>
        </geometry>
      </visual>
    </link>
    <joint name='right_wrist_roll_joint' type='revolute'>
      <child>right_wrist_roll_link</child>
      <parent>right_wrist_yaw_link</parent>
      <axis>
        <xyz>-0.999996 -0 -0.002696</xyz>
        <limit>
          <lower>-1</lower>
          <upper>1</upper>
          <effort>1</effort>
          <velocity>1</velocity>
        </limit>
        <dynamics>
          <spring_reference>0</spring_reference>
          <spring_stiffness>0</spring_stiffness>
        </dynamics>
        <use_parent_model_frame>1</use_parent_model_frame>
      </axis>
    </joint>
    <link name='right_top_parallel_link'>
      <pose frame=''>0 0 -0.21537 1.5708 0 3.14159</pose>
      <inertial>
        <pose frame=''>0.038219 -0 0.06975 0 -0 0</pose>
        <mass>0.10494</mass>
        <inertia>
          <ixx>0</ixx>
          <ixy>0</ixy>
          <ixz>0</ixz>
          <iyy>0</iyy>
          <iyz>0</iyz>
          <izz>0</izz>
        </inertia>
      </inertial>
      <collision name='right_top_parallel_link_collision'>
        <pose frame=''>0 0 0 0 -0 0</pose>
        <geometry>
          <mesh>
            <scale>1 1 1</scale>
            <uri>model://MTM/meshes/right_top_parallel_link.STL</uri>
          </mesh>
        </geometry>
      </collision>
      <visual name='right_top_parallel_link_visual'>
        <pose frame=''>0 0 0 0 -0 0</pose>
        <geometry>
          <mesh>
            <scale>1 1 1</scale>
            <uri>model://MTM/meshes/right_top_parallel_link.STL</uri>
          </mesh>
        </geometry>
      </visual>
    </link>
    <joint name='right_shoulder_pitch_parallel_joint' type='revolute'>
      <child>right_top_parallel_link</child>
      <parent>right_outer_yaw_link</parent>
      <axis>
        <xyz>-7e-06 -1 4e-06</xyz>
        <limit>
          <lower>-1</lower>
          <upper>1</upper>
          <effort>0</effort>
          <velocity>0</velocity>
        </limit>
        <dynamics>
          <spring_reference>0</spring_reference>
          <spring_stiffness>0</spring_stiffness>
        </dynamics>
        <use_parent_model_frame>1</use_parent_model_frame>
      </axis>
    </joint>
    <link name='right_front_parallel_link'>
      <pose frame=''>-0.1011 1e-06 -0.21537 1.57206 1.5679 -3.14033</pose>
      <inertial>
        <pose frame=''>0.1397 0 0.0265 0 -0 0</pose>
        <mass>0.041436</mass>
        <inertia>
          <ixx>0</ixx>
          <ixy>0</ixy>
          <ixz>0</ixz>
          <iyy>0</iyy>
          <iyz>0</iyz>
          <izz>0</izz>
        </inertia>
      </inertial>
      <collision name='right_front_parallel_link_collision'>
        <pose frame=''>0 0 0 0 -0 0</pose>
        <geometry>
          <mesh>
            <scale>1 1 1</scale>
            <uri>model://MTM/meshes/right_front_parallel_link.STL</uri>
          </mesh>
        </geometry>
      </collision>
      <visual name='right_front_parallel_link_visual'>
        <pose frame=''>0 0 0 0 -0 0</pose>
        <geometry>
          <mesh>
            <scale>1 1 1</scale>
            <uri>model://MTM/meshes/right_front_parallel_link.STL</uri>
          </mesh>
        </geometry>
      </visual>
    </link>
    <joint name='right_front_shoulder_pitch_joint' type='revolute'>
      <child>right_front_parallel_link</child>
      <parent>right_top_parallel_link</parent>
      <axis>
        <xyz>-7e-06 -1 4e-06</xyz>
        <limit>
          <lower>-1</lower>
          <upper>1</upper>
          <effort>0</effort>
          <velocity>0</velocity>
        </limit>
        <dynamics>
          <spring_reference>0</spring_reference>
          <spring_stiffness>0</spring_stiffness>
        </dynamics>
        <use_parent_model_frame>1</use_parent_model_frame>
      </axis>
    </joint>
  </model>
</sdf>
