<?xml version='1.0'?>
<sdf version='1.6'>
  <model name='dvrk_mtm'>
    <link name='right_top_panel'>
      <pose>0 0 1 0 -0 0</pose>
      <inertial>
        <pose>0.03648 0.008713 0.040499 0 -0 0</pose>
        <mass>0.58739</mass>
        <inertia>
          <ixx>0.001</ixx>
          <ixy>0</ixy>
          <ixz>0</ixz>
          <iyy>0.001</iyy>
          <iyz>0</iyz>
          <izz>0.001</izz>
        </inertia>
      </inertial>
      <collision name='right_top_panel_collision'>
        <pose>0 0 0 0 0 0</pose>
        <geometry>
          <mesh>
            <scale>1 1 1</scale>
            <uri>model://MTM/meshes/right_top_panel.STL</uri>
          </mesh>
        </geometry>
      </collision>
      <visual name='right_top_panel_visual'>
        <pose>0 0 0 0 -0 0</pose>
        <geometry>
          <mesh>
            <scale>1 1 1</scale>
            <uri>model://MTM/meshes/right_top_panel.STL</uri>
          </mesh>
        </geometry>
      </visual>
    </link>

    <!--joint name='right_fixed_joint' type='fixed'>
      <child>right_top_panel</child>
      <parent>world</parent>
    </joint-->

    <link name='right_outer_yaw_link'>
      <pose>0 0 0.78463 0 0 0</pose>
      <inertial>
        <pose>0.013424 0.062051 0.13219 0 -0 0</pose>
        <mass>2</mass>
        <inertia>
          <ixx>0.003</ixx>
          <ixy>0</ixy>
          <ixz>0</ixz>
          <iyy>0.003</iyy>
          <iyz>0</iyz>
          <izz>0.003</izz>
        </inertia>
      </inertial>
      <collision name='right_outer_yaw_link_collision'>
        <pose>0 0 0 0 -0 0</pose>
        <geometry>
          <mesh>
            <scale>1 1 1</scale>
            <uri>model://MTM/meshes/right_outer_yaw_link.STL</uri>
          </mesh>
        </geometry>
      </collision>
      <visual name='right_outer_yaw_link_visual'>
        <pose>0 0 0 0 -0 0</pose>
        <geometry>
          <mesh>
            <scale>1 1 1</scale>
            <uri>model://MTM/meshes/right_outer_yaw_link.STL</uri>
          </mesh>
        </geometry>
      </visual>
    </link>

    <joint name='right_outer_yaw_joint' type='revolute'>
      <child>right_outer_yaw_link</child>
      <parent>right_top_panel</parent>
      <axis>
        <xyz>0 0 1</xyz>
        <limit>
          <lower>-1</lower>
          <upper>1</upper>
          <effort>1</effort>
          <velocity>1</velocity>
        </limit>
        <dynamics>
          <spring_reference>0</spring_reference>
          <spring_stiffness>0</spring_stiffness>
        </dynamics>
        <use_parent_model_frame>1</use_parent_model_frame>
      </axis>
    </joint>

    

    <link name='right_back_parallel_link'>
      <pose frame=''>0 0 0.78463 -1.57079 1.57079 0</pose>
      <inertial>
        <pose frame=''>0.076362 -0.007849 0.00814 0 -0 0</pose>
        <mass>2</mass>
        <inertia>
          <ixx>0.001</ixx>
          <ixy>0</ixy>
          <ixz>0</ixz>
          <iyy>0.035</iyy>
          <iyz>0</iyz>
          <izz>0.035</izz>
        </inertia>
      </inertial>
      <collision name='right_back_parallel_link_collision'>
        <pose frame=''>0 0 0 0 -0 0</pose>
        <geometry>
          <mesh>
            <scale>1 1 1</scale>
            <uri>model://MTM/meshes/right_back_parallel_link.STL</uri>
          </mesh>
        </geometry>
      </collision>
      <visual name='right_back_parallel_link_visual'>
        <pose frame=''>0 0 0 0 -0 0</pose>
        <geometry>
          <mesh>
            <scale>1 1 1</scale>
            <uri>model://MTM/meshes/right_back_parallel_link.STL</uri>
          </mesh>
        </geometry>
      </visual>
    </link>
    <joint name='right_shoulder_pitch_joint' type='revolute'>
      <child>right_back_parallel_link</child>
      <parent>right_outer_yaw_link</parent>
      <axis>
        <xyz>4e-06 1 -0</xyz>
        <limit>
          <lower>-1</lower>
          <upper>1</upper>
          <effort>1</effort>
          <velocity>1</velocity>
        </limit>
        <dynamics>
          <spring_reference>0</spring_reference>
          <spring_stiffness>0</spring_stiffness>
        </dynamics>
        <use_parent_model_frame>1</use_parent_model_frame>
      </axis>
    </joint>
    
    <link name='right_bottom_parallel_link'>
      <pose frame=''>0 -0 0.50496  1.57079 0 3.1415926</pose>
      <inertial>
        <pose frame=''>0.18263 0.005514 0 0 -0 0</pose>
        <mass>1</mass>
        <inertia>
          <ixx>0.0002</ixx>
          <ixy>0</ixy>
          <ixz>0</ixz>
          <iyy>0.02</iyy>
          <iyz>0</iyz>
          <izz>0.02</izz>
        </inertia>
      </inertial>
      <collision name='right_bottom_parallel_link_collision'>
        <pose frame=''>0 0 0 0 -0 0</pose>
        <geometry>
          <mesh>
            <scale>1 1 1</scale>
            <uri>model://MTM/meshes/right_bottom_parallel_link.STL</uri>
          </mesh>
        </geometry>
      </collision>
      <visual name='right_bottom_parallel_link_visual'>
        <pose frame=''>0 0 0 0 -0 0</pose>
        <geometry>
          <mesh>
            <scale>1 1 1</scale>
            <uri>model://MTM/meshes/right_bottom_parallel_link.STL</uri>
          </mesh>
        </geometry>
      </visual>
    </link>
    <joint name='right_elbow_pitch_joint' type='revolute'>
      <child>right_bottom_parallel_link</child>
      <parent>right_back_parallel_link</parent>
      <axis>
        <xyz>0 1 0</xyz>
        <limit>
          <lower>-1</lower>
          <upper>1</upper>
          <effort>1</effort>
          <velocity>1</velocity>
        </limit>
        <dynamics>
          <spring_reference>0</spring_reference>
          <spring_stiffness>0</spring_stiffness>
        </dynamics>
        <use_parent_model_frame>1</use_parent_model_frame>
      </axis>
    </joint>

    <link name='right_wrist_platform_link'>
      <pose frame=''>-0.364091 0 0.656544 0 0 3.1415926</pose>
      <inertial>
        <pose frame=''>0 0.075884 -0.079722 0 -0 0</pose>
        <mass>0.5</mass>
        <inertia>
          <ixx>0.0002</ixx>
          <ixy>0</ixy>
          <ixz>0</ixz>
          <iyy>0.0002</iyy>
          <iyz>0</iyz>
          <izz>0.0002</izz>
        </inertia>
      </inertial>
      <collision name='right_wrist_platform_link_collision'>
        <pose frame=''>0 0 0 0 -0 0</pose>
        <geometry>
          <mesh>
            <scale>1 1 1</scale>
            <uri>model://MTM/meshes/right_wrist_platform_link.STL</uri>
          </mesh>
        </geometry>
      </collision>
      <visual name='right_wrist_platform_link_visual'>
        <pose frame=''>0 0 0 0 -0 0</pose>
        <geometry>
          <mesh>
            <scale>1 1 1</scale>
            <uri>model://MTM/meshes/right_wrist_platform_link.STL</uri>
          </mesh>
        </geometry>
      </visual>
    </link>
    <joint name='right_wrist_platform_joint' type='revolute'>
      <child>right_wrist_platform_link</child>
      <parent>right_bottom_parallel_link</parent>
      <axis>
        <xyz>0 0 1</xyz>
        <limit>
          <lower>-1</lower>
          <upper>1</upper>
          <effort>1</effort>
          <velocity>1</velocity>
        </limit>
        <dynamics>
          <spring_reference>0</spring_reference>
          <spring_stiffness>0</spring_stiffness>
        </dynamics>
        <use_parent_model_frame>1</use_parent_model_frame>
      </axis>
    </joint>
    <link name='right_wrist_pitch_link'>
      <pose frame=''>-0.364091 0 0.656544 1.5708 0 3.1415926</pose>
      <inertial>
        <pose frame=''>9.6e-05 -0.061955 -0.044889 0 -0 0</pose>
        <mass>0.1</mass>
        <inertia>
          <ixx>0.00001</ixx>
          <ixy>0</ixy>
          <ixz>0</ixz>
          <iyy>0.00001</iyy>
          <iyz>0</iyz>
          <izz>0.00001</izz>
        </inertia>
      </inertial>
      <collision name='right_wrist_pitch_link_collision'>
        <pose frame=''>0 0 0 0 -0 0</pose>
        <geometry>
          <mesh>
            <scale>1 1 1</scale>
            <uri>model://MTM/meshes/right_wrist_pitch_link.STL</uri>
          </mesh>
        </geometry>
      </collision>
      <visual name='right_wrist_pitch_link_visual'>
        <pose frame=''>0 0 0 0 -0 0</pose>
        <geometry>
          <mesh>
            <scale>1 1 1</scale>
            <uri>model://MTM/meshes/right_wrist_pitch_link.STL</uri>
          </mesh>
        </geometry>
      </visual>
    </link>
    <joint name='right_wrist_pitch_joint' type='revolute'>
      <child>right_wrist_pitch_link</child>
      <parent>right_wrist_platform_link</parent>
      <axis>
        <xyz>0 1 -0</xyz>
        <limit>
          <lower>-1</lower>
          <upper>1</upper>
          <effort>1</effort>
          <velocity>1</velocity>
        </limit>
        <dynamics>
          <spring_reference>0</spring_reference>
          <spring_stiffness>0</spring_stiffness>
        </dynamics>
        <use_parent_model_frame>1</use_parent_model_frame>
      </axis>
    </joint>
    <link name='right_wrist_yaw_link'>
      <pose frame=''>-0.364091 0 0.656544 3.1389 3.14159 1.5708</pose>
      <inertial>
        <pose frame=''>-0.002136 0.049256 -0.031864 0 -0 0</pose>
        <mass>0.05</mass>
        <inertia>
          <ixx>0.00001</ixx>
          <ixy>0</ixy>
          <ixz>0</ixz>
          <iyy>0.00001</iyy>
          <iyz>0</iyz>
          <izz>0.00001</izz>
        </inertia>
      </inertial>
      <collision name='right_wrist_yaw_link_collision'>
        <pose frame=''>0 0 0 0 -0 0</pose>
        <geometry>
          <mesh>
            <scale>1 1 1</scale>
            <uri>model://MTM/meshes/right_wrist_yaw_link.STL</uri>
          </mesh>
        </geometry>
      </collision>
      <visual name='right_wrist_yaw_link_visual'>
        <pose frame=''>0 0 0 0 -0 0</pose>
        <geometry>
          <mesh>
            <scale>1 1 1</scale>
            <uri>model://MTM/meshes/right_wrist_yaw_link.STL</uri>
          </mesh>
        </geometry>
      </visual>
    </link>
    <joint name='right_wrist_yaw_joint' type='revolute'>
      <child>right_wrist_yaw_link</child>
      <parent>right_wrist_pitch_link</parent>
      <axis>
        <xyz>0 0 1</xyz>
        <limit>
          <lower>-1</lower>
          <upper>1</upper>
          <effort>1</effort>
          <velocity>1</velocity>
        </limit>
        <dynamics>
          <spring_reference>0</spring_reference>
          <spring_stiffness>0</spring_stiffness>
        </dynamics>
        <use_parent_model_frame>1</use_parent_model_frame>
      </axis>
    </joint>
    <link name='right_wrist_roll_link'>
      <pose frame=''>-0.364091 0 0.656544 -1.57349 3.14159 1.5708</pose>
      <inertial>
        <pose frame=''>0 0 -0.014612 0 0 0</pose>
        <mass>0.02</mass>
        <inertia>
          <ixx>0.00001</ixx>
          <ixy>0</ixy>
          <ixz>0</ixz>
          <iyy>0.00001</iyy>
          <iyz>0</iyz>
          <izz>0.000001</izz>
        </inertia>
      </inertial>
      <collision name='right_wrist_roll_link_collision'>
        <pose frame=''>0 0 0 0 -0 0</pose>
        <geometry>
          <mesh>
            <scale>1 1 1</scale>
            <uri>model://MTM/meshes/right_wrist_roll_link.STL</uri>
          </mesh>
        </geometry>
      </collision>
      <visual name='right_wrist_roll_link_visual'>
        <pose frame=''>0 0 0 0 -0 0</pose>
        <geometry>
          <mesh>
            <scale>1 1 1</scale>
            <uri>model://MTM/meshes/right_wrist_roll_link.STL</uri>
          </mesh>
        </geometry>
      </visual>
    </link>
    <joint name='right_wrist_roll_joint' type='revolute'>
      <child>right_wrist_roll_link</child>
      <parent>right_wrist_yaw_link</parent>
      <axis>
        <xyz>-1 0 0</xyz>
        <limit>
          <lower>-1</lower>
          <upper>1</upper>
          <effort>1</effort>
          <velocity>1</velocity>
        </limit>
        <dynamics>
          <spring_reference>0</spring_reference>
          <spring_stiffness>0</spring_stiffness>
        </dynamics>
        <use_parent_model_frame>1</use_parent_model_frame>
      </axis>
    </joint>
    
    <link name='right_top_parallel_link'>
      <pose frame=''>0 0 0.78463 1.5708 0 3.14159</pose>
      <inertial>
        <pose frame=''>0 0 0 0 0 0</pose>
        <mass>2</mass>
        <inertia>
          <ixx>0.003</ixx>
          <ixy>0</ixy>
          <ixz>0</ixz>
          <iyy>0.003</iyy>
          <iyz>0</iyz>
          <izz>0.003</izz>
        </inertia>
      </inertial>
      <collision name='right_top_parallel_link_collision'>
        <pose frame=''>0 0 0 0 -0 0</pose>
        <geometry>
          <mesh>
            <scale>1 1 1</scale>
            <uri>model://MTM/meshes/right_top_parallel_link.STL</uri>
          </mesh>
        </geometry>
      </collision>
      <visual name='right_top_parallel_link_visual'>
        <pose frame=''>0 0 0 0 -0 0</pose>
        <geometry>
          <mesh>
            <scale>1 1 1</scale>
            <uri>model://MTM/meshes/right_top_parallel_link.STL</uri>
          </mesh>
        </geometry>
      </visual>
    </link>
    <joint name='right_shoulder_pitch_parallel_joint' type='revolute'>
      <child>right_top_parallel_link</child>
      <parent>right_outer_yaw_link</parent>
      <axis>
        <xyz>0 1 0</xyz>
        <limit>
          <lower>-1</lower>
          <upper>1</upper>
          <effort>0</effort>
          <velocity>0</velocity>
        </limit>
        <dynamics>
          <spring_reference>0</spring_reference>
          <spring_stiffness>0</spring_stiffness>
        </dynamics>
        <use_parent_model_frame>1</use_parent_model_frame>
      </axis>
    </joint>
    
    <link name='right_front_parallel_link'>
      <pose frame=''>-0.1011 0 0.78463 1.57206 1.5679 -3.14033</pose>
      <inertial>
        <pose frame=''>0.1397 0 0.0265 0 -0 0</pose>
        <mass>0.05</mass>
        <inertia>
          <ixx>0.000001</ixx>
          <ixy>0</ixy>
          <ixz>0</ixz>
          <iyy>0.0002</iyy>
          <iyz>0</iyz>
          <izz>0.0002</izz>
        </inertia>
      </inertial>
      <collision name='right_front_parallel_link_collision'>
        <pose frame=''>0 0 0 0 -0 0</pose>
        <geometry>
          <mesh>
            <scale>1 1 1</scale>
            <uri>model://MTM/meshes/right_front_parallel_link.STL</uri>
          </mesh>
        </geometry>
      </collision>
      <visual name='right_front_parallel_link_visual'>
        <pose frame=''>0 0 0 0 -0 0</pose>
        <geometry>
          <mesh>
            <scale>1 1 1</scale>
            <uri>model://MTM/meshes/right_front_parallel_link.STL</uri>
          </mesh>
        </geometry>
      </visual>
    </link>
    <joint name='right_front_shoulder_pitch_joint' type='revolute'>
      <child>right_front_parallel_link</child>
      <parent>right_top_parallel_link</parent>
      <axis>
        <xyz>0 1 0</xyz>
        <limit>
          <lower>-1</lower>
          <upper>1</upper>
          <effort>0</effort>
          <velocity>0</velocity>
        </limit>
        <dynamics>
          <spring_reference>0</spring_reference>
          <spring_stiffness>0</spring_stiffness>
        </dynamics>
        <use_parent_model_frame>1</use_parent_model_frame>
      </axis>
    </joint>

    <joint name='right_front_elbow_pitch_joint' type='revolute'>
      <pose>0.1011 0 0 0 0 0 </pose>
      <child>right_bottom_parallel_link</child>
      <parent>right_front_parallel_link</parent>
      <axis>
        <xyz>0 1 0</xyz>
        <limit>
          <lower>-3.14</lower>
          <upper>3.14</upper>
          <effort>100</effort>
          <velocity>10</velocity>
        </limit>
        <dynamics>
          <spring_reference>0</spring_reference>
          <spring_stiffness>0</spring_stiffness>
        </dynamics>
        <use_parent_model_frame>1</use_parent_model_frame>
      </axis>
    </joint>

  </model>
</sdf>
