<sdf version='1.6'>
  <model name='PSM_PACKAGE'>
    <link name='base_link'>
      <pose frame=''>0 0 0 0 -0 0</pose>
      <inertial>
        <pose frame=''>-0 -0.170155 -0.085607 0 -0 0</pose>
        <mass>2.01612</mass>
        <inertia>
          <ixx>0</ixx>
          <ixy>0</ixy>
          <ixz>0</ixz>
          <iyy>0</iyy>
          <iyz>0</iyz>
          <izz>0</izz>
        </inertia>
      </inertial>
      <collision name='base_link_collision'>
        <pose frame=''>0 0 0 0 -0 0</pose>
        <geometry>
          <mesh>
            <scale>1 1 1</scale>
            <uri>model://PSM_PACKAGE/meshes/base_link.STL</uri>
          </mesh>
        </geometry>
      </collision>
      <visual name='base_link_visual'>
        <pose frame=''>0 0 0 0 -0 0</pose>
        <geometry>
          <mesh>
            <scale>1 1 1</scale>
            <uri>model://PSM_PACKAGE/meshes/base_link.STL</uri>
          </mesh>
        </geometry>
      </visual>
    </link>
    <link name='yaw_Link'>
      <pose frame=''>0 0 0 1.58642 -1.57079 -3e-06</pose>
      <inertial>
        <pose frame=''>-0.038769 7.8e-05 0.041596 0 -0 0</pose>
        <mass>1.47048</mass>
        <inertia>
          <ixx>0</ixx>
          <ixy>0</ixy>
          <ixz>0</ixz>
          <iyy>0</iyy>
          <iyz>0</iyz>
          <izz>0</izz>
        </inertia>
      </inertial>
      <collision name='yaw_Link_collision'>
        <pose frame=''>0 0 0 0 -0 0</pose>
        <geometry>
          <mesh>
            <scale>1 1 1</scale>
            <uri>model://PSM_PACKAGE/meshes/yaw_Link.STL</uri>
          </mesh>
        </geometry>
      </collision>
      <visual name='yaw_Link_visual'>
        <pose frame=''>0 0 0 0 -0 0</pose>
        <geometry>
          <mesh>
            <scale>1 1 1</scale>
            <uri>model://PSM_PACKAGE/meshes/yaw_Link.STL</uri>
          </mesh>
        </geometry>
      </visual>
    </link>
    <joint name='yaw_joint' type='revolute'>
      <child>yaw_Link</child>
      <parent>base_link</parent>
      <axis>
        <xyz>0 1 -0</xyz>
        <limit>
          <lower>-1e+16</lower>
          <upper>1e+16</upper>
        </limit>
        <dynamics>
          <spring_reference>0</spring_reference>
          <spring_stiffness>0</spring_stiffness>
        </dynamics>
        <use_parent_model_frame>1</use_parent_model_frame>
      </axis>
    </joint>
    <link name='pitch_back_Link'>
      <pose frame=''>-0 -0.0296 0 1.57079 -1.28007 -1.5708</pose>
      <inertial>
        <pose frame=''>-0.011651 -0.036241 3.6e-05 0 -0 0</pose>
        <mass>0.984945</mass>
        <inertia>
          <ixx>0</ixx>
          <ixy>0</ixy>
          <ixz>0</ixz>
          <iyy>0</iyy>
          <iyz>0</iyz>
          <izz>0</izz>
        </inertia>
      </inertial>
      <collision name='pitch_back_Link_collision'>
        <pose frame=''>0 0 0 0 -0 0</pose>
        <geometry>
          <mesh>
            <scale>1 1 1</scale>
            <uri>model://PSM_PACKAGE/meshes/pitch_back_Link.STL</uri>
          </mesh>
        </geometry>
      </collision>
      <visual name='pitch_back_Link_visual'>
        <pose frame=''>0 0 0 0 -0 0</pose>
        <geometry>
          <mesh>
            <scale>1 1 1</scale>
            <uri>model://PSM_PACKAGE/meshes/pitch_back_Link.STL</uri>
          </mesh>
        </geometry>
      </visual>
    </link>
    <joint name='pitch_back_joint' type='revolute'>
      <child>pitch_back_Link</child>
      <parent>yaw_Link</parent>
      <axis>
        <xyz>-1 4e-06 1e-06</xyz>
        <limit>
          <lower>-1e+16</lower>
          <upper>1e+16</upper>
        </limit>
        <dynamics>
          <spring_reference>0</spring_reference>
          <spring_stiffness>0</spring_stiffness>
        </dynamics>
        <use_parent_model_frame>1</use_parent_model_frame>
      </axis>
    </joint>
    <link name='counterweight_Link'>
      <pose frame=''>-0 -0.1296 -0 5e-06 -2.6e-05 1.57079</pose>
      <inertial>
        <pose frame=''>0.008649 -1e-06 -0.042832 0 -0 0</pose>
        <mass>0.0572295</mass>
        <inertia>
          <ixx>0</ixx>
          <ixy>0</ixy>
          <ixz>0</ixz>
          <iyy>0</iyy>
          <iyz>0</iyz>
          <izz>0</izz>
        </inertia>
      </inertial>
      <collision name='counterweight_Link_collision'>
        <pose frame=''>0 0 0 0 -0 0</pose>
        <geometry>
          <mesh>
            <scale>1 1 1</scale>
            <uri>model://PSM_PACKAGE/meshes/counterweight_Link.STL</uri>
          </mesh>
        </geometry>
      </collision>
      <visual name='counterweight_Link_visual'>
        <pose frame=''>0 0 0 0 -0 0</pose>
        <geometry>
          <mesh>
            <scale>1 1 1</scale>
            <uri>model://PSM_PACKAGE/meshes/counterweight_Link.STL</uri>
          </mesh>
        </geometry>
      </visual>
    </link>
    <joint name='counterweight_joint' type='prismatic'>
      <child>counterweight_Link</child>
      <parent>pitch_back_Link</parent>
      <axis>
        <xyz>5e-06 -2.6e-05 1</xyz>
        <limit>
          <lower>0</lower>
          <upper>0</upper>
          <effort>0</effort>
          <velocity>0</velocity>
        </limit>
        <dynamics>
          <spring_reference>0</spring_reference>
          <spring_stiffness>0</spring_stiffness>
        </dynamics>
        <use_parent_model_frame>1</use_parent_model_frame>
      </axis>
    </joint>
    <link name='pitch_bottom_Link'>
      <pose frame=''>-0 -0.072598 0.143705 -1.5708 -2.6e-05 1.57079</pose>
      <inertial>
        <pose frame=''>0.256832 -0.010348 -6e-06 0 -0 0</pose>
        <mass>0.445695</mass>
        <inertia>
          <ixx>0</ixx>
          <ixy>0</ixy>
          <ixz>0</ixz>
          <iyy>0</iyy>
          <iyz>0</iyz>
          <izz>0</izz>
        </inertia>
      </inertial>
      <collision name='pitch_bottom_Link_collision'>
        <pose frame=''>0 0 0 0 -0 0</pose>
        <geometry>
          <mesh>
            <scale>1 1 1</scale>
            <uri>model://PSM_PACKAGE/meshes/pitch_bottom_Link.STL</uri>
          </mesh>
        </geometry>
      </collision>
      <visual name='pitch_bottom_Link_visual'>
        <pose frame=''>0 0 0 0 -0 0</pose>
        <geometry>
          <mesh>
            <scale>1 1 1</scale>
            <uri>model://PSM_PACKAGE/meshes/pitch_bottom_Link.STL</uri>
          </mesh>
        </geometry>
      </visual>
    </link>
    <joint name='pitch_bottom_joint' type='revolute'>
      <child>pitch_bottom_Link</child>
      <parent>pitch_back_Link</parent>
      <axis>
        <xyz>-1 4e-06 1e-06</xyz>
        <limit>
          <lower>-1e+16</lower>
          <upper>1e+16</upper>
        </limit>
        <dynamics>
          <spring_reference>0</spring_reference>
          <spring_stiffness>0</spring_stiffness>
        </dynamics>
        <use_parent_model_frame>1</use_parent_model_frame>
      </axis>
    </joint>
    <link name='pitch_end_Link'>
      <pose frame=''>2e-06 0.443402 0.143719 -1.5708 -2.6e-05 1.57079</pose>
      <inertial>
        <pose frame=''>-0.001929 -0.136127 -0 0 -0 0</pose>
        <mass>2.09102</mass>
        <inertia>
          <ixx>0</ixx>
          <ixy>0</ixy>
          <ixz>0</ixz>
          <iyy>0</iyy>
          <iyz>0</iyz>
          <izz>0</izz>
        </inertia>
      </inertial>
      <collision name='pitch_end_Link_collision'>
        <pose frame=''>0 0 0 0 -0 0</pose>
        <geometry>
          <mesh>
            <scale>1 1 1</scale>
            <uri>model://PSM_PACKAGE/meshes/pitch_end_Link.STL</uri>
          </mesh>
        </geometry>
      </collision>
      <visual name='pitch_end_Link_visual'>
        <pose frame=''>0 0 0 0 -0 0</pose>
        <geometry>
          <mesh>
            <scale>1 1 1</scale>
            <uri>model://PSM_PACKAGE/meshes/pitch_end_Link.STL</uri>
          </mesh>
        </geometry>
      </visual>
    </link>
    <joint name='pitch_end_joint' type='revolute'>
      <child>pitch_end_Link</child>
      <parent>pitch_bottom_Link</parent>
      <axis>
        <xyz>-1 4e-06 1e-06</xyz>
        <limit>
          <lower>-1e+16</lower>
          <upper>1e+16</upper>
        </limit>
        <dynamics>
          <spring_reference>0</spring_reference>
          <spring_stiffness>0</spring_stiffness>
        </dynamics>
        <use_parent_model_frame>1</use_parent_model_frame>
      </axis>
    </joint>
    <link name='main_insertion_Link'>
      <pose frame=''>2e-06 0.486395 0.43181 -3.14159 1.9e-05 -1.5708</pose>
      <inertial>
        <pose frame=''>0.004056 -0.000109 0.010465 0 -0 0</pose>
        <mass>0.224909</mass>
        <inertia>
          <ixx>1.79437e-05</ixx>
          <ixy>-6.21725e-08</ixy>
          <ixz>1.26596e-05</ixz>
          <iyy>2.6875e-05</iyy>
          <iyz>8.81214e-08</iyz>
          <izz>8.93216e-06</izz>
        </inertia>
      </inertial>
      <collision name='main_insertion_Link_collision'>
        <pose frame=''>0 0 0 0 -0 0</pose>
        <geometry>
          <mesh>
            <scale>1 1 1</scale>
            <uri>model://PSM_PACKAGE/meshes/main_insertion_Link.STL</uri>
          </mesh>
        </geometry>
      </collision>
      <visual name='main_insertion_Link_visual'>
        <pose frame=''>0 0 0 0 -0 0</pose>
        <geometry>
          <mesh>
            <scale>1 1 1</scale>
            <uri>model://PSM_PACKAGE/meshes/main_insertion_Link.STL</uri>
          </mesh>
        </geometry>
      </visual>
    </link>
    <joint name='main_insertion_joint' type='prismatic'>
      <child>main_insertion_Link</child>
      <parent>pitch_end_Link</parent>
      <axis>
        <xyz>-3e-06 -1.9e-05 1</xyz>
        <limit>
          <lower>0</lower>
          <upper>0</upper>
          <effort>0</effort>
          <velocity>0</velocity>
        </limit>
        <dynamics>
          <spring_reference>0</spring_reference>
          <spring_stiffness>0</spring_stiffness>
        </dynamics>
        <use_parent_model_frame>1</use_parent_model_frame>
      </axis>
    </joint>
    <link name='tool_roll_link'>
      <pose frame=''>3e-06 0.486403 0.01491 3.14159 -1.9e-05 1.5708</pose>
      <inertial>
        <pose frame=''>-0 -0 -0.005823 0 -0 0</pose>
        <mass>0.000332249</mass>
        <inertia>
          <ixx>0</ixx>
          <ixy>0</ixy>
          <ixz>0</ixz>
          <iyy>0</iyy>
          <iyz>0</iyz>
          <izz>0</izz>
        </inertia>
      </inertial>
      <collision name='tool_roll_link_collision'>
        <pose frame=''>0 0 0 0 -0 0</pose>
        <geometry>
          <mesh>
            <scale>1 1 1</scale>
            <uri>model://PSM_PACKAGE/meshes/tool_roll_link.STL</uri>
          </mesh>
        </geometry>
      </collision>
      <visual name='tool_roll_link_visual'>
        <pose frame=''>0 0 0 0 -0 0</pose>
        <geometry>
          <mesh>
            <scale>1 1 1</scale>
            <uri>model://PSM_PACKAGE/meshes/tool_roll_link.STL</uri>
          </mesh>
        </geometry>
      </visual>
    </link>
    <joint name='tool_roll_joint' type='revolute'>
      <child>tool_roll_link</child>
      <parent>main_insertion_Link</parent>
      <axis>
        <xyz>-3e-06 -1.9e-05 1</xyz>
        <limit>
          <lower>-1e+16</lower>
          <upper>1e+16</upper>
        </limit>
        <dynamics>
          <spring_reference>0</spring_reference>
          <spring_stiffness>0</spring_stiffness>
        </dynamics>
        <use_parent_model_frame>1</use_parent_model_frame>
      </axis>
    </joint>
    <link name='tool_pitch_link'>
      <pose frame=''>3e-06 0.486403 0.01491 -1.74034 1.57078 1.40125</pose>
      <inertial>
        <pose frame=''>0.003577 -4.9e-05 4e-06 0 -0 0</pose>
        <mass>0.000259766</mass>
        <inertia>
          <ixx>1.49982e-13</ixx>
          <ixy>1.93241e-12</ixy>
          <ixz>4.19072e-12</ixz>
          <iyy>1.42117e-10</iyy>
          <iyz>-5.70325e-14</iyz>
          <izz>1.42019e-10</izz>
        </inertia>
      </inertial>
      <collision name='tool_pitch_link_collision'>
        <pose frame=''>0 0 0 0 -0 0</pose>
        <geometry>
          <mesh>
            <scale>1 1 1</scale>
            <uri>model://PSM_PACKAGE/meshes/tool_pitch_link.STL</uri>
          </mesh>
        </geometry>
      </collision>
      <visual name='tool_pitch_link_visual'>
        <pose frame=''>0 0 0 0 -0 0</pose>
        <geometry>
          <mesh>
            <scale>1 1 1</scale>
            <uri>model://PSM_PACKAGE/meshes/tool_pitch_link.STL</uri>
          </mesh>
        </geometry>
      </visual>
    </link>
    <joint name='tool_pitch_joint' type='revolute'>
      <child>tool_pitch_link</child>
      <parent>tool_roll_link</parent>
      <axis>
        <xyz>1 0 3e-06</xyz>
        <limit>
          <lower>-1e+16</lower>
          <upper>1e+16</upper>
        </limit>
        <dynamics>
          <spring_reference>0</spring_reference>
          <spring_stiffness>0</spring_stiffness>
        </dynamics>
        <use_parent_model_frame>1</use_parent_model_frame>
      </axis>
    </joint>
    <link name='tool_yaw_link'>
      <pose frame=''>3e-06 0.486453 0.00581 1.57078 -1e-06 -3.14159</pose>
      <inertial>
        <pose frame=''>-0 -0 -5e-05 0 -0 0</pose>
        <mass>6.63661e-06</mass>
        <inertia>
          <ixx>0</ixx>
          <ixy>0</ixy>
          <ixz>0</ixz>
          <iyy>0</iyy>
          <iyz>0</iyz>
          <izz>0</izz>
        </inertia>
      </inertial>
      <collision name='tool_yaw_link_collision'>
        <pose frame=''>0 0 0 0 -0 0</pose>
        <geometry>
          <mesh>
            <scale>1 1 1</scale>
            <uri>model://PSM_PACKAGE/meshes/tool_yaw_link.STL</uri>
          </mesh>
        </geometry>
      </collision>
      <visual name='tool_yaw_link_visual'>
        <pose frame=''>0 0 0 0 -0 0</pose>
        <geometry>
          <mesh>
            <scale>1 1 1</scale>
            <uri>model://PSM_PACKAGE/meshes/tool_yaw_link.STL</uri>
          </mesh>
        </geometry>
      </visual>
    </link>
    <joint name='tool_yaw_joint' type='revolute'>
      <child>tool_yaw_link</child>
      <parent>tool_pitch_link</parent>
      <axis>
        <xyz>-0 1 1.2e-05</xyz>
        <limit>
          <lower>-1e+16</lower>
          <upper>1e+16</upper>
        </limit>
        <dynamics>
          <spring_reference>0</spring_reference>
          <spring_stiffness>0</spring_stiffness>
        </dynamics>
        <use_parent_model_frame>1</use_parent_model_frame>
      </axis>
    </joint>
    <link name='tool_gripper1_link'>
      <pose frame=''>3e-06 0.486453 0.00581 1.57078 -1e-06 -3.14159</pose>
      <inertial>
        <pose frame=''>0.000189 0.001353 -0.000867 0 -0 0</pose>
        <mass>3.90696e-05</mass>
        <inertia>
          <ixx>0</ixx>
          <ixy>0</ixy>
          <ixz>0</ixz>
          <iyy>0</iyy>
          <iyz>0</iyz>
          <izz>0</izz>
        </inertia>
      </inertial>
      <collision name='tool_gripper1_link_collision'>
        <pose frame=''>0 0 0 0 -0 0</pose>
        <geometry>
          <mesh>
            <scale>1 1 1</scale>
            <uri>model://PSM_PACKAGE/meshes/tool_gripper1_link.STL</uri>
          </mesh>
        </geometry>
      </collision>
      <visual name='tool_gripper1_link_visual'>
        <pose frame=''>0 0 0 0 -0 0</pose>
        <geometry>
          <mesh>
            <scale>1 1 1</scale>
            <uri>model://PSM_PACKAGE/meshes/tool_gripper1_link.STL</uri>
          </mesh>
        </geometry>
      </visual>
    </link>
    <joint name='tool_gripper1_joint' type='revolute'>
      <child>tool_gripper1_link</child>
      <parent>tool_yaw_link</parent>
      <axis>
        <xyz>-0 1 1.2e-05</xyz>
        <limit>
          <lower>-1e+16</lower>
          <upper>1e+16</upper>
        </limit>
        <dynamics>
          <spring_reference>0</spring_reference>
          <spring_stiffness>0</spring_stiffness>
        </dynamics>
        <use_parent_model_frame>1</use_parent_model_frame>
      </axis>
    </joint>
    <link name='tool_gripper2_link'>
      <pose frame=''>3e-06 0.486453 0.00581 1.57078 -1e-06 -3.14159</pose>
      <inertial>
        <pose frame=''>-0.000189 0.001353 0.000867 0 -0 0</pose>
        <mass>3.90696e-05</mass>
        <inertia>
          <ixx>0</ixx>
          <ixy>0</ixy>
          <ixz>0</ixz>
          <iyy>0</iyy>
          <iyz>0</iyz>
          <izz>0</izz>
        </inertia>
      </inertial>
      <collision name='tool_gripper2_link_collision'>
        <pose frame=''>0 0 0 0 -0 0</pose>
        <geometry>
          <mesh>
            <scale>1 1 1</scale>
            <uri>model://PSM_PACKAGE/meshes/tool_gripper2_link.STL</uri>
          </mesh>
        </geometry>
      </collision>
      <visual name='tool_gripper2_link_visual'>
        <pose frame=''>0 0 0 0 -0 0</pose>
        <geometry>
          <mesh>
            <scale>1 1 1</scale>
            <uri>model://PSM_PACKAGE/meshes/tool_gripper2_link.STL</uri>
          </mesh>
        </geometry>
      </visual>
    </link>
    <joint name='tool_gripper2_joint' type='revolute'>
      <child>tool_gripper2_link</child>
      <parent>tool_yaw_link</parent>
      <axis>
        <xyz>-0 1 1.2e-05</xyz>
        <limit>
          <lower>-1e+16</lower>
          <upper>1e+16</upper>
        </limit>
        <dynamics>
          <spring_reference>0</spring_reference>
          <spring_stiffness>0</spring_stiffness>
        </dynamics>
        <use_parent_model_frame>1</use_parent_model_frame>
      </axis>
    </joint>
    <link name='pitch_top_Link'>
      <pose frame=''>0 -0.068718 0.18 -1.5708 -2.6e-05 1.57079</pose>
      <inertial>
        <pose frame=''>0.31246 -0.000566 -0 0 -0 0</pose>
        <mass>0.178407</mass>
        <inertia>
          <ixx>0</ixx>
          <ixy>0</ixy>
          <ixz>0</ixz>
          <iyy>0</iyy>
          <iyz>0</iyz>
          <izz>0</izz>
        </inertia>
      </inertial>
      <collision name='pitch_top_Link_collision'>
        <pose frame=''>0 0 0 0 -0 0</pose>
        <geometry>
          <mesh>
            <scale>1 1 1</scale>
            <uri>model://PSM_PACKAGE/meshes/pitch_top_Link.STL</uri>
          </mesh>
        </geometry>
      </collision>
      <visual name='pitch_top_Link_visual'>
        <pose frame=''>0 0 0 0 -0 0</pose>
        <geometry>
          <mesh>
            <scale>1 1 1</scale>
            <uri>model://PSM_PACKAGE/meshes/pitch_top_Link.STL</uri>
          </mesh>
        </geometry>
      </visual>
    </link>
    <joint name='pitch_top_joint' type='revolute'>
      <child>pitch_top_Link</child>
      <parent>pitch_back_Link</parent>
      <axis>
        <xyz>-1 4e-06 1e-06</xyz>
        <limit>
          <lower>-1e+16</lower>
          <upper>1e+16</upper>
        </limit>
        <dynamics>
          <spring_reference>0</spring_reference>
          <spring_stiffness>0</spring_stiffness>
        </dynamics>
        <use_parent_model_frame>1</use_parent_model_frame>
      </axis>
    </joint>
    <link name='pitch_front_Link'>
      <pose frame=''>0 0.0664 0 1.57079 -1.28007 -1.5708</pose>
      <inertial>
        <pose frame=''>0.096269 0 0.047551 0 -0 0</pose>
        <mass>0.0744253</mass>
        <inertia>
          <ixx>0</ixx>
          <ixy>0</ixy>
          <ixz>0</ixz>
          <iyy>0</iyy>
          <iyz>0</iyz>
          <izz>0</izz>
        </inertia>
      </inertial>
      <collision name='pitch_front_Link_collision'>
        <pose frame=''>0 0 0 0 -0 0</pose>
        <geometry>
          <mesh>
            <scale>1 1 1</scale>
            <uri>model://PSM_PACKAGE/meshes/pitch_front_Link.STL</uri>
          </mesh>
        </geometry>
      </collision>
      <visual name='pitch_front_Link_visual'>
        <pose frame=''>0 0 0 0 -0 0</pose>
        <geometry>
          <mesh>
            <scale>1 1 1</scale>
            <uri>model://PSM_PACKAGE/meshes/pitch_front_Link.STL</uri>
          </mesh>
        </geometry>
      </visual>
    </link>
    <joint name='pitch_front_joint' type='revolute'>
      <child>pitch_front_Link</child>
      <parent>yaw_Link</parent>
      <axis>
        <xyz>-1 4e-06 1e-06</xyz>
        <limit>
          <lower>-1e+16</lower>
          <upper>1e+16</upper>
        </limit>
        <dynamics>
          <spring_reference>0</spring_reference>
          <spring_stiffness>0</spring_stiffness>
        </dynamics>
        <use_parent_model_frame>1</use_parent_model_frame>
      </axis>
    </joint>
  </model>
</sdf>
