<robot
  name="PSM_PACKAGE">
  <link
    name="base_link">
    <inertial>
      <origin
        xyz="-1.218799738518E-08 -0.170155334863205 -0.0856068339372725"
        rpy="0 0 0" />
      <mass
        value="2.01611935350024" />
      <inertia
        ixx="0"
        ixy="0"
        ixz="0"
        iyy="0"
        iyz="0"
        izz="0" />
    </inertial>
    <visual>
      <origin
        xyz="0 0 0"
        rpy="0 0 0" />
      <geometry>
        <mesh
          filename="package://PSM_PACKAGE/meshes/base_link.STL" />
      </geometry>
      <material
        name="">
        <color
          rgba="0.898039215686275 0.917647058823529 0.929411764705882 1" />
      </material>
    </visual>
    <collision>
      <origin
        xyz="0 0 0"
        rpy="0 0 0" />
      <geometry>
        <mesh
          filename="package://PSM_PACKAGE/meshes/base_link.STL" />
      </geometry>
    </collision>
  </link>
  <link
    name="yaw_Link">
    <inertial>
      <origin
        xyz="-0.038768826895421 7.84810687538258E-05 0.0415960702785929"
        rpy="0 0 0" />
      <mass
        value="1.47048370646334" />
      <inertia
        ixx="0"
        ixy="0"
        ixz="0"
        iyy="0"
        iyz="0"
        izz="0" />
    </inertial>
    <visual>
      <origin
        xyz="0 0 0"
        rpy="0 0 0" />
      <geometry>
        <mesh
          filename="package://PSM_PACKAGE/meshes/yaw_Link.STL" />
      </geometry>
      <material
        name="">
        <color
          rgba="0.898039215686275 0.917647058823529 0.929411764705882 1" />
      </material>
    </visual>
    <collision>
      <origin
        xyz="0 0 0"
        rpy="0 0 0" />
      <geometry>
        <mesh
          filename="package://PSM_PACKAGE/meshes/yaw_Link.STL" />
      </geometry>
    </collision>
  </link>
  <joint
    name="yaw_joint"
    type="continuous">
    <origin
      xyz="0 0 0"
      rpy="1.57079632679489 -1.5707963267949 0" />
    <parent
      link="base_link" />
    <child
      link="yaw_Link" />
    <axis
      xyz="0 0 -1" />
  </joint>
  <link
    name="pitch_back_Link">
    <inertial>
      <origin
        xyz="-0.0116509415966225 -0.0362409831473348 3.55759910590909E-05"
        rpy="0 0 0" />
      <mass
        value="0.984944647833389" />
      <inertia
        ixx="0"
        ixy="0"
        ixz="0"
        iyy="0"
        iyz="0"
        izz="0" />
    </inertial>
    <visual>
      <origin
        xyz="0 0 0"
        rpy="0 0 0" />
      <geometry>
        <mesh
          filename="package://PSM_PACKAGE/meshes/pitch_back_Link.STL" />
      </geometry>
      <material
        name="">
        <color
          rgba="0.898039215686275 0.917647058823529 0.929411764705882 1" />
      </material>
    </visual>
    <collision>
      <origin
        xyz="0 0 0"
        rpy="0 0 0" />
      <geometry>
        <mesh
          filename="package://PSM_PACKAGE/meshes/pitch_back_Link.STL" />
      </geometry>
    </collision>
  </link>
  <joint
    name="pitch_back_joint"
    type="continuous">
    <origin
      xyz="0 0 0.0296"
      rpy="-1.5708 -0.29073 1.7787E-15" />
    <parent
      link="yaw_Link" />
    <child
      link="pitch_back_Link" />
    <axis
      xyz="0 0 1" />
  </joint>
  <link
    name="pitch_bottom_Link">
    <inertial>
      <origin
        xyz="0.256832099418569 -0.0103480348656514 -6.17918787845137E-06"
        rpy="0 0 0" />
      <mass
        value="0.445694866856226" />
      <inertia
        ixx="0"
        ixy="0"
        ixz="0"
        iyy="0"
        iyz="0"
        izz="0" />
    </inertial>
    <visual>
      <origin
        xyz="0 0 0"
        rpy="0 0 0" />
      <geometry>
        <mesh
          filename="package://PSM_PACKAGE/meshes/pitch_bottom_Link.STL" />
      </geometry>
      <material
        name="">
        <color
          rgba="0.898039215686275 0.917647058823529 0.929411764705882 1" />
      </material>
    </visual>
    <collision>
      <origin
        xyz="0 0 0"
        rpy="0 0 0" />
      <geometry>
        <mesh
          filename="package://PSM_PACKAGE/meshes/pitch_bottom_Link.STL" />
      </geometry>
    </collision>
  </link>
  <joint
    name="pitch_bottom_joint"
    type="continuous">
    <origin
      xyz="0.15 0 0"
      rpy="0 0 1.8615" />
    <parent
      link="pitch_back_Link" />
    <child
      link="pitch_bottom_Link" />
    <axis
      xyz="0 0 1" />
  </joint>
  <link
    name="pitch_end_Link">
    <inertial>
      <origin
        xyz="-0.00192933659672778 -0.13612686758295 -5.97042575610683E-08"
        rpy="0 0 0" />
      <mass
        value="2.09102449600226" />
      <inertia
        ixx="0"
        ixy="0"
        ixz="0"
        iyy="0"
        iyz="0"
        izz="0" />
    </inertial>
    <visual>
      <origin
        xyz="0 0 0"
        rpy="0 0 0" />
      <geometry>
        <mesh
          filename="package://PSM_PACKAGE/meshes/pitch_end_Link.STL" />
      </geometry>
      <material
        name="">
        <color
          rgba="0.898039215686275 0.917647058823529 0.929411764705882 1" />
      </material>
    </visual>
    <collision>
      <origin
        xyz="0 0 0"
        rpy="0 0 0" />
      <geometry>
        <mesh
          filename="package://PSM_PACKAGE/meshes/pitch_end_Link.STL" />
      </geometry>
    </collision>
  </link>
  <joint
    name="pitch_end_joint"
    type="continuous">
    <origin
      xyz="0.516000000000004 0 0"
      rpy="0 0 -4.29558764834341E-13" />
    <parent
      link="pitch_bottom_Link" />
    <child
      link="pitch_end_Link" />
    <axis
      xyz="0 0 1" />
  </joint>
  <link
    name="main_insertion_Link">
    <inertial>
      <origin
        xyz="0.00405627466206293 -0.000109340705171561 0.0104645658395064"
        rpy="0 0 0" />
      <mass
        value="0.224908528510799" />
      <inertia
        ixx="1.79436848992526E-05"
        ixy="-6.21725156718615E-08"
        ixz="1.26595521175575E-05"
        iyy="2.68749808161646E-05"
        iyz="8.81213737729348E-08"
        izz="8.93216146530439E-06" />
    </inertial>
    <visual>
      <origin
        xyz="0 0 0"
        rpy="0 0 0" />
      <geometry>
        <mesh
          filename="package://PSM_PACKAGE/meshes/main_insertion_Link.STL" />
      </geometry>
      <material
        name="">
        <color
          rgba="1 0.556862745098039 0.0588235294117647 0.4" />
      </material>
    </visual>
    <collision>
      <origin
        xyz="0 0 0"
        rpy="0 0 0" />
      <geometry>
        <mesh
          filename="package://PSM_PACKAGE/meshes/main_insertion_Link.STL" />
      </geometry>
    </collision>
  </link>
  <joint
    name="main_insertion_joint"
    type="prismatic">
    <origin
      xyz="0.043 -0.28809 0"
      rpy="1.5708 0 3.1416" />
    <parent
      link="pitch_end_Link" />
    <child
      link="main_insertion_Link" />
    <axis
      xyz="0 0 -1" />
    <limit
      effort="0"
      velocity="0" />
  </joint>
  <link
    name="tool_roll_link">
    <inertial>
      <origin
        xyz="-1.1310785863472E-08 -7.45590006904056E-09 -0.00582338133566149"
        rpy="0 0 0" />
      <mass
        value="0.000332248646148611" />
      <inertia
        ixx="0"
        ixy="0"
        ixz="0"
        iyy="0"
        iyz="0"
        izz="0" />
    </inertial>
    <visual>
      <origin
        xyz="0 0 0"
        rpy="0 0 0" />
      <geometry>
        <mesh
          filename="package://PSM_PACKAGE/meshes/tool_roll_link.STL" />
      </geometry>
      <material
        name="">
        <color
          rgba="0.796078431372549 0.823529411764706 0.937254901960784 1" />
      </material>
    </visual>
    <collision>
      <origin
        xyz="0 0 0"
        rpy="0 0 0" />
      <geometry>
        <mesh
          filename="package://PSM_PACKAGE/meshes/tool_roll_link.STL" />
      </geometry>
    </collision>
  </link>
  <joint
    name="tool_roll_joint"
    type="continuous">
    <origin
      xyz="0 0 0.4169"
      rpy="4.0037E-15 2.5989E-29 -3.1416" />
    <parent
      link="main_insertion_Link" />
    <child
      link="tool_roll_link" />
    <axis
      xyz="0 0 -1" />
  </joint>
  <link
    name="tool_pitch_link">
    <inertial>
      <origin
        xyz="0.00357661239129972 -4.86748958434813E-05 4.44129526631568E-06"
        rpy="0 0 0" />
      <mass
        value="0.000259766323068838" />
      <inertia
        ixx="1.49981979951931E-13"
        ixy="1.93241332354976E-12"
        ixz="4.19072395860641E-12"
        iyy="1.4211666515159E-10"
        iyz="-5.7032472380205E-14"
        izz="1.42019280436736E-10" />
    </inertial>
    <visual>
      <origin
        xyz="0 0 0"
        rpy="0 0 0" />
      <geometry>
        <mesh
          filename="package://PSM_PACKAGE/meshes/tool_pitch_link.STL" />
      </geometry>
      <material
        name="">
        <color
          rgba="0.796078431372549 0.823529411764706 0.937254901960784 1" />
      </material>
    </visual>
    <collision>
      <origin
        xyz="0 0 0"
        rpy="0 0 0" />
      <geometry>
        <mesh
          filename="package://PSM_PACKAGE/meshes/tool_pitch_link.STL" />
      </geometry>
    </collision>
  </link>
  <joint
    name="tool_pitch_joint"
    type="continuous">
    <origin
      xyz="0 0 0"
      rpy="1.5708 -1.5708 0" />
    <parent
      link="tool_roll_link" />
    <child
      link="tool_pitch_link" />
    <axis
      xyz="0 0 -1" />
  </joint>
  <link
    name="tool_yaw_link">
    <inertial>
      <origin
        xyz="-3.38952951650343E-15 -1.5779044737485E-13 -5.00000011357526E-05"
        rpy="0 0 0" />
      <mass
        value="6.6366144807084E-06" />
      <inertia
        ixx="0"
        ixy="0"
        ixz="0"
        iyy="0"
        iyz="0"
        izz="0" />
    </inertial>
    <visual>
      <origin
        xyz="0 0 0"
        rpy="0 0 0" />
      <geometry>
        <mesh
          filename="package://PSM_PACKAGE/meshes/tool_yaw_link.STL" />
      </geometry>
      <material
        name="">
        <color
          rgba="0.796078431372549 0.823529411764706 0.937254901960784 1" />
      </material>
    </visual>
    <collision>
      <origin
        xyz="0 0 0"
        rpy="0 0 0" />
      <geometry>
        <mesh
          filename="package://PSM_PACKAGE/meshes/tool_yaw_link.STL" />
      </geometry>
    </collision>
  </link>
  <joint
    name="tool_yaw_joint"
    type="continuous">
    <origin
      xyz="0.0091 -5E-05 0"
      rpy="1.5708 -1.5708 0" />
    <parent
      link="tool_pitch_link" />
    <child
      link="tool_yaw_link" />
    <axis
      xyz="0 0 1" />
  </joint>
  <link
    name="tool_gripper1_link">
    <inertial>
      <origin
        xyz="0.000188736724872208 0.00135264310260425 -0.000866946464327167"
        rpy="0 0 0" />
      <mass
        value="3.90695979761291E-05" />
      <inertia
        ixx="0"
        ixy="0"
        ixz="0"
        iyy="0"
        iyz="0"
        izz="0" />
    </inertial>
    <visual>
      <origin
        xyz="0 0 0"
        rpy="0 0 0" />
      <geometry>
        <mesh
          filename="package://PSM_PACKAGE/meshes/tool_gripper1_link.STL" />
      </geometry>
      <material
        name="">
        <color
          rgba="0.796078431372549 0.823529411764706 0.937254901960784 1" />
      </material>
    </visual>
    <collision>
      <origin
        xyz="0 0 0"
        rpy="0 0 0" />
      <geometry>
        <mesh
          filename="package://PSM_PACKAGE/meshes/tool_gripper1_link.STL" />
      </geometry>
    </collision>
  </link>
  <joint
    name="tool_gripper1_joint"
    type="continuous">
    <origin
      xyz="0 0 0"
      rpy="0 0 0" />
    <parent
      link="tool_yaw_link" />
    <child
      link="tool_gripper1_link" />
    <axis
      xyz="0 0 1" />
  </joint>
  <link
    name="tool_gripper2_link">
    <inertial>
      <origin
        xyz="-0.000188736724878972 0.00135264310260425 0.000866946462056095"
        rpy="0 0 0" />
      <mass
        value="3.90695979761291E-05" />
      <inertia
        ixx="0"
        ixy="0"
        ixz="0"
        iyy="0"
        iyz="0"
        izz="0" />
    </inertial>
    <visual>
      <origin
        xyz="0 0 0"
        rpy="0 0 0" />
      <geometry>
        <mesh
          filename="package://PSM_PACKAGE/meshes/tool_gripper2_link.STL" />
      </geometry>
      <material
        name="">
        <color
          rgba="0.796078431372549 0.823529411764706 0.937254901960784 1" />
      </material>
    </visual>
    <collision>
      <origin
        xyz="0 0 0"
        rpy="0 0 0" />
      <geometry>
        <mesh
          filename="package://PSM_PACKAGE/meshes/tool_gripper2_link.STL" />
      </geometry>
    </collision>
  </link>
  <joint
    name="tool_gripper2_joint"
    type="continuous">
    <origin
      xyz="0 0 0"
      rpy="0 0 0" />
    <parent
      link="tool_yaw_link" />
    <child
      link="tool_gripper2_link" />
    <axis
      xyz="0 0 1" />
  </joint>
  <link
    name="pitch_top_Link">
    <inertial>
      <origin
        xyz="0.312459561160537 -0.000565655662915554 -3.41314856443592E-07"
        rpy="0 0 0" />
      <mass
        value="0.178406510206941" />
      <inertia
        ixx="0"
        ixy="0"
        ixz="0"
        iyy="0"
        iyz="0"
        izz="0" />
    </inertial>
    <visual>
      <origin
        xyz="0 0 0"
        rpy="0 0 0" />
      <geometry>
        <mesh
          filename="package://PSM_PACKAGE/meshes/pitch_top_Link.STL" />
      </geometry>
      <material
        name="">
        <color
          rgba="0.898039215686275 0.917647058823529 0.929411764705882 1" />
      </material>
    </visual>
    <collision>
      <origin
        xyz="0 0 0"
        rpy="0 0 0" />
      <geometry>
        <mesh
          filename="package://PSM_PACKAGE/meshes/pitch_top_Link.STL" />
      </geometry>
    </collision>
  </link>
  <joint
    name="pitch_top_joint"
    type="continuous">
    <origin
      xyz="0.18366 0.014121 0"
      rpy="0 0 1.8615" />
    <parent
      link="pitch_back_Link" />
    <child
      link="pitch_top_Link" />
    <axis
      xyz="0 0 1" />
  </joint>
  <link
    name="counterweight_Link">
    <inertial>
      <origin
        xyz="0.00864945005675316 -7.99999995084467E-07 -0.0428319993376596"
        rpy="0 0 0" />
      <mass
        value="0.0572294566812767" />
      <inertia
        ixx="0"
        ixy="0"
        ixz="0"
        iyy="0"
        iyz="0"
        izz="0" />
    </inertial>
    <visual>
      <origin
        xyz="0 0 0"
        rpy="0 0 0" />
      <geometry>
        <mesh
          filename="package://PSM_PACKAGE/meshes/counterweight_Link.STL" />
      </geometry>
      <material
        name="">
        <color
          rgba="0.792156862745098 0.819607843137255 0.933333333333333 1" />
      </material>
    </visual>
    <collision>
      <origin
        xyz="0 0 0"
        rpy="0 0 0" />
      <geometry>
        <mesh
          filename="package://PSM_PACKAGE/meshes/counterweight_Link.STL" />
      </geometry>
    </collision>
  </link>
  <joint
    name="counterweight_joint"
    type="prismatic">
    <origin
      xyz="0.028665 -0.095804 0"
      rpy="1.5708 0 1.8615" />
    <parent
      link="pitch_back_Link" />
    <child
      link="counterweight_Link" />
    <axis
      xyz="0 0 1" />
    <limit
      effort="0"
      velocity="0" />
  </joint>
  <link
    name="pitch_front_Link">
    <inertial>
      <origin
        xyz="0.0962686548282791 8.6763929374456E-14 0.0475509864128363"
        rpy="0 0 0" />
      <mass
        value="0.0744252818496182" />
      <inertia
        ixx="0"
        ixy="0"
        ixz="0"
        iyy="0"
        iyz="0"
        izz="0" />
    </inertial>
    <visual>
      <origin
        xyz="0 0 0"
        rpy="0 0 0" />
      <geometry>
        <mesh
          filename="package://PSM_PACKAGE/meshes/pitch_front_Link.STL" />
      </geometry>
      <material
        name="">
        <color
          rgba="0.898039215686275 0.917647058823529 0.929411764705882 1" />
      </material>
    </visual>
    <collision>
      <origin
        xyz="0 0 0"
        rpy="0 0 0" />
      <geometry>
        <mesh
          filename="package://PSM_PACKAGE/meshes/pitch_front_Link.STL" />
      </geometry>
    </collision>
  </link>
  <joint
    name="pitch_front_joint"
    type="continuous">
    <origin
      xyz="0 0 -0.0664"
      rpy="-1.5708 -0.29073 1.7787E-15" />
    <parent
      link="yaw_Link" />
    <child
      link="pitch_front_Link" />
    <axis
      xyz="0 0 1" />
  </joint>
</robot>